<?xml version="1.0"?>
<robot name="hdt_6dof" xmlns:xacro="http://www.ros.org/wiki/xacro">

	<!-- constants -->
	<xacro:property name="PI" value="3.1415926535897931"/>

	<!-- materials -->
	<material name="default_material">
		<color rgba="${255/255} ${255/255} ${255/255} 1.0"/>
	</material>

	<!-- import gazebo definitions -->
	<xacro:include filename="$(find hdt_6dof_description)/urdf/hdt_6dof.gazebo" />

	<!-- segment 0 -->
	<link name="world"/>

	<!-- segment 1 -->
	<joint name="joint1" type="revolute">
		<hdt id="1"/>
		<axis xyz="0 0 1"/>
		<limit effort="60.0" lower="-2.0944" upper="2.0944" velocity="2.0944"/>
		<origin rpy="0 0 0" xyz="0 0 0"/>
		<parent link="world"/>
		<child link="link1"/>
    	<dynamics damping="0.7" friction="0.0"/>
	</joint>

	<transmission name="tran1">
		<type>transmission_interface/SimpleTransmission</type>
		<joint name="joint1"/>
		<actuator name="motor1">
			<hardwareInterface>EffortJointInterface</hardwareInterface>
			<mechanicalReduction>1</mechanicalReduction>
		</actuator>
	</transmission>

	<link name="link1">
<!--
		<collision>
			<origin xyz="0 0 0.0461" rpy="0 0 0"/>
			<geometry>
				<cylinder length="0.09217" radius="0.035865"/>
			</geometry>
		</collision>
-->

		<visual>
			<origin xyz="0 0 0" rpy="0 0 0"/>
			<geometry>
				<mesh filename="package://hdt_6dof_description/meshes/hdt_6dof_1.STL"/>
			</geometry>
			<material name="default_material"/>
		</visual>

		<inertial>
		<origin xyz="0 0 0.04488" rpy="0 0 0"/>
		<mass value="1.00775"/>
			<inertia
			ixx="0.00104342" ixy="0.0" ixz="0.0"
			iyy="0.00104342" iyz="0.0"
			izz="0.00064952"/>
		</inertial>
	</link>

	<joint name="joint1f" type="fixed">
		<parent link="link1"/>
		<child link="link2a"/>
		<origin rpy="0 0 0" xyz="0 0 0.09217"/>
	</joint>

	<link name="link2a">
<!--
		<collision>
			<origin xyz="0 0 0.0553" rpy="0 0 0"/>
			<geometry>
				<cylinder length="0.11062" radius="0.03571"/>
			</geometry>
		</collision>
-->

		<visual>
			<origin xyz="0 0 0.0" rpy="0 0 0"/>
			<geometry>
				<mesh filename="package://hdt_6dof_description/meshes/hdt_6dof_2a.STL"/>
			</geometry>
			<material name="default_material"/>
		</visual>

		<inertial>
			<origin xyz="0 0 0.04417" rpy="0 0 0"/>
			<mass value="0.66775"/>
			<inertia
			ixx="0.000912914" ixy="0.0" ixz="0.0"
			iyy="0.001102412" iyz="0.0"
			izz="0.00062987"/>
		</inertial>
	</link>

	<!-- segment 2 -->
	<joint name="joint2" type="revolute">
		<hdt id="2"/>
		<axis xyz="1 0 0"/>
		<limit effort="60.0" lower="-2.0944" upper="2.0944" velocity="2.0944"/>
		<origin rpy="0 0 0" xyz="0 0 0.07"/>
		<parent link="link2a"/>
		<child link="link2b"/>
    	<dynamics damping="0.7" friction="0.0"/>
	</joint>

	<transmission name="tran2">
		<type>transmission_interface/SimpleTransmission</type>
		<joint name="joint2"/>
		<actuator name="motor2">
			<hardwareInterface>EffortJointInterface</hardwareInterface>
			<mechanicalReduction>1</mechanicalReduction>
		</actuator>
	</transmission>

	<link name="link2b">
		<visual>
			<origin xyz="0 0 0.0" rpy="0 0 0"/>
			<geometry>
				<mesh filename="package://hdt_6dof_description/meshes/hdt_6dof_2b.STL"/>
			</geometry>
			<material name="default_material"/>
		</visual>

		<inertial>
			<origin xyz="0 0 0.02018" rpy="0 0 0"/>
			<mass value="0.69896"/>
			<inertia
			ixx="0.000941825" ixy="0.0" ixz="0.0"
			iyy="0.000881162" iyz="0.0"
			izz="0.000329923"/>
		</inertial>
	</link>

	<!-- segment 3 -->
	<joint name="joint2f" type="fixed">
		<origin xyz="0 0 0.077" rpy="0 0 0" />
		<parent link="link2b"/>
		<child link="link3"/>
	</joint>

	<link name="link3">
		<visual>
			<origin xyz="0 0 0.0" rpy="0 0 0"/>
			<geometry>
				<mesh filename="package://hdt_6dof_description/meshes/hdt_6dof_3.STL"/>
			</geometry>
			<material name="default_material"/>
		</visual>

		<inertial>
			<origin xyz="0 0 0.12528" rpy="0 0 0"/>
			<mass value="2.76251"/>
			<inertia
			ixx="0.015653102" ixy="0.0" ixz="0.0"
			iyy="0.015653102" iyz="0.0"
			izz="0.001778082"/>
		</inertial>
	</link>

	<joint name="joint3f" type="fixed">
		<origin rpy="0 0 0" xyz="0 0 0.253"/>
		<parent link="link3"/>
		<child link="link4a"/>
	</joint>

	<link name="link4a">
		<visual>
			<origin xyz="0 0 0.0" rpy="0 0 0"/>
			<geometry>
				<mesh filename="package://hdt_6dof_description/meshes/hdt_6dof_4a.STL"/>
			</geometry>
			<material name="default_material"/>
		</visual>

		<inertial>
			<origin xyz="0 0 0.04417" rpy="0 0 0"/>
			<mass value="0.66775"/>
			<inertia
			ixx="0.000912914" ixy="0.0" ixz="0.0"
			iyy="0.001102412" iyz="0.0"
			izz="0.00062987"/>
		</inertial>
	</link>

	<!-- segment 4 -->
	<joint name="joint4" type="revolute">
		<hdt id="4"/>
		<axis xyz="1 0 0"/>
		<limit effort="60.0" lower="-1.5708" upper="1.5708" velocity="2.0944"/>
		<origin xyz="0 0 0.07" rpy="0 0 0"/>
		<parent link="link4a"/>
		<child link="link4b"/>
		<dynamics damping="0.7" friction="0.0"/>
	</joint>

	<transmission name="tran4">
		<type>transmission_interface/SimpleTransmission</type>
		<joint name="joint4"/>
		<actuator name="motor4">
			<hardwareInterface>EffortJointInterface</hardwareInterface>
			<mechanicalReduction>1</mechanicalReduction>
		</actuator>
	</transmission>

	<link name="link4b">
		<visual>
			<origin xyz="0 0 0.0" rpy="0 0 0"/>
			<geometry>
				<mesh filename="package://hdt_6dof_description/meshes/hdt_6dof_4b.STL"/>
			</geometry>
			<material name="default_material"/>
		</visual>

		<inertial>
			<origin xyz="0 -0.02126 0.03702" rpy="0 0 0"/>
			<mass value="0.18911"/>
			<inertia
			ixx="0.000375485" ixy="0.000000486" ixz="-0.000000844"
			iyy="0.000332021" iyz="-0.0000969"
			izz="0.000156947"/>
		</inertial>
	</link>

	<!-- segment 5 -->
	<joint name="joint5" type="revolute">
		<hdt id="5"/>
		<axis xyz="0 -1 0"/>
		<limit effort="60.0" lower="-2.0944" upper="2.0944" velocity="2.0944"/>
		<origin xyz="0 -0.0413 0.074" rpy="0 0 0"/>
		<parent link="link4b"/>
		<child link="link5"/>
		<dynamics damping="0.7" friction="0.0"/>
	</joint>

	<transmission name="tran5">
		<type>transmission_interface/SimpleTransmission</type>
		<joint name="joint5"/>
		<actuator name="motor5">
			<hardwareInterface>EffortJointInterface</hardwareInterface>
			<mechanicalReduction>1</mechanicalReduction>
		</actuator>
	</transmission>

	<link name="link5">
		<visual>
			<origin xyz="0 0 0.0" rpy="0 0 0"/>
			<geometry>
				<mesh filename="package://hdt_6dof_description/meshes/hdt_6dof_5.STL"/>
			</geometry>
			<material name="default_material"/>
		</visual>

		<inertial>
			<origin xyz="0 -0.1478 0" rpy="0 0 0"/>
			<mass value="3.27531"/>
			<inertia
			ixx="0.025657659" ixy="0.0" ixz="0.0"
			iyy="0.002107885" iyz="0.0"
			izz="0.025657659"/>
		</inertial>
	</link>

	<joint name="joint5f" type="fixed">
		<origin xyz="0 -0.3 0" rpy="0 0 0"/>
		<parent link="link5"/>
		<child link="link6a"/>
	</joint>

	<link name="link6a">
		<visual>
			<origin xyz="0 0 0.0" rpy="0 0 0"/>
			<geometry>
				<mesh filename="package://hdt_6dof_description/meshes/hdt_6dof_6a.STL"/>
			</geometry>
			<material name="default_material"/>
		</visual>

		<inertial>
			<origin xyz="0 -0.04112 0" rpy="0 0 0"/>
			<mass value="0.50058"/>
			<inertia
			ixx="0.000580228" ixy="0.0" ixz="0.0"
			iyy="0.000541503" iyz="0.0"
			izz="0.000750977"/>
		</inertial>
	</link>

	<!-- segment 6 -->
	<joint name="joint6" type="revolute">
		<hdt id="6"/>
		<axis xyz="1 0 0"/>
		<limit effort="60.0" lower="-1.5708" upper="1.5708" velocity="2.0944"/>
		<origin xyz="0 -0.055 0" rpy="0 0 0"/>
		<parent link="link6a"/>
		<child link="link6b"/>
		<dynamics damping="0.7" friction="0.0"/>
	</joint>

	<transmission name="tran6">
		<type>transmission_interface/SimpleTransmission</type>
		<joint name="joint6"/>
		<actuator name="motor6">
			<hardwareInterface>EffortJointInterface</hardwareInterface>
			<mechanicalReduction>1</mechanicalReduction>
		</actuator>
	</transmission>

	<link name="link6b">
		<visual>
			<origin xyz="0 0 0.0" rpy="0 0 0"/>
			<geometry>
				<mesh filename="package://hdt_6dof_description/meshes/hdt_6dof_6b.STL"/>
			</geometry>
			<material name="default_material"/>
		</visual>

		<inertial>
			<origin xyz="0 -0.03855 0" rpy="0 0 0"/>
			<mass value="0.99934"/>
			<inertia
			ixx="0.001905243" ixy="0.0" ixz="0.0"
			iyy="0.000474765" iyz="0.0"
			izz="0.001905243"/>
		</inertial>
	</link>

	<!-- segment 7 -->
	<joint name="joint7" type="revolute">
		<hdt id="7"/>
		<axis xyz="0 0 1"/>
		<limit effort="60.0" lower="-1.5708" upper="1.5708" velocity="2.0944"/>
		<origin xyz="0 -0.0771 0" rpy="0 0 0"/>
		<parent link="link6b"/>
		<child link="link7"/>
		<dynamics damping="0.7" friction="0.0"/>
	</joint>

	<transmission name="tran7">
		<type>transmission_interface/SimpleTransmission</type>
		<joint name="joint7"/>
		<actuator name="motor7">
			<hardwareInterface>EffortJointInterface</hardwareInterface>
			<mechanicalReduction>1</mechanicalReduction>
		</actuator>
	</transmission>

	<link name="link7">
		<visual>
			<origin xyz="0 0 0.0" rpy="0 0 0"/>
			<geometry>
				<mesh filename="package://hdt_6dof_description/meshes/hdt_6dof_7.STL"/>
			</geometry>
			<material name="default_material"/>
		</visual>

		<inertial>
			<origin xyz="0 -0.01177 0" rpy="0 0 0"/>
			<mass value="0.47608"/>
			<inertia
			ixx="0.000705091" ixy="0.0" ixz="0.0"
			iyy="0.000537081" iyz="0.0"
			izz="0.000534342"/>
		</inertial>
	</link>
</robot>

